Workbook

Sheet DASHBOARD
B1: 🔬 REFERRAL RECOMMENDATION DASHBOARD
B2: Laboratory & Hospital Referral Scoring System – Routine & Cito
B3: ⚙ SELECT PARAMETERS
B4: 📋 Test Type | G4: 🧪 Test Name | M4: 📅 Today is
B5: Routine | G5: C3 | M5: Thursday
B7: 🏆 TOP 3 RECOMMENDATION
B8: 🥇 RANK 1 | G8: 🥇 RANK 2 | L8: 🥇 RANK 3
B9: Name | C9: =HELPER!$B$69 -> Hospital A | G9: Name | H9: =HELPER!$B$70 -> Hospital C | L9: Name | M9: =HELPER!$B$71 -> Hospital D
B10: Price | C10: =HELPER!C69 -> 600000 | G10: Price | H10: =HELPER!$C$70 -> 600000 | L10: Price | M10: =HELPER!$C$71 -> 610000
B11: Schedule | C11: =HELPER!$E$69 -> Mon,Tue,Wed,Thu,Fri,Sat | G11: Schedule | H11: =HELPER!$E$70 -> Mon,Tue,Wed,Thu,Fri,Sat | L11: Schedule | M11: =HELPER!$E$71 -> Mon,Tue,Wed,Thu,Fri,Sat
B12: TAT | C12: =HELPER!$D$69&" DAYS" -> 3 DAYS | G12: TAT | H12: =HELPER!$D$70&" DAYS" -> 3 DAYS | L12: TAT | M12: =HELPER!$D$71&" DAYS" -> 3 DAYS
B13: Pick up | C13: =HELPER!$F$69 -> NO | G13: Pick up | H13: =HELPER!$F$70 -> NO | L13: Pick up | M13: =HELPER!$F$71 -> NO
B14: Score | C14: =HELPER!$G$69 -> 93.25 | G14: Score | H14: =HELPER!$G$70 -> 88 | L14: Score | M14: =HELPER!$G$71 -> 80.25
B16: 📊 COMPARISON CHARTS
B46: 📋 OTHER AVAILABLE REFERRALS (Ranked by Score)
B48: Rank | C48: Lab Name | E48: Price (Rp) | G48: Schedule | J48: TAT | K48: Pickup | M48: Final Score
B49: 4 | C49: =HELPER!$B$72 -> Laboratorium B | E49: =HELPER!$C$72 -> 800000 | G49: =HELPER!$E$72 -> Mon,Tue,Wed,Thu,Fri | J49: =HELPER!$D72 -> 2 | K49: =HELPER!$F72 -> YES | M49: =HELPER!$G72 -> 74
B50: 5 | C50: =HELPER!$B$73 -> Hospital B | E50: =HELPER!$C$73 -> 615000 | G50: =HELPER!$E$73 -> Mon,Tue,Wed,Thu,Fri,Sat | J50: =HELPER!$D73 -> 3 | K50: =HELPER!$F73 -> NO | M50: =HELPER!$G73 -> 73.75
B51: 6 | C51: =HELPER!$B$74 -> Laboratorium C | E51: =HELPER!$C$74 -> 815000 | G51: =HELPER!$E$74 -> Mon,Tue,Wed,Thu,Fri | J51: =HELPER!$D74 -> 2 | K51: =HELPER!$F74 -> NO | M51: =HELPER!$G74 -> 63
B52: 7 | C52: =HELPER!$B$75 -> Laboratorium D | E52: =HELPER!$C$75 -> 820000 | G52: =HELPER!$E$75 -> Mon,Tue,Wed,Thu,Fri | J52: =HELPER!$D75 -> 2 | K52: =HELPER!$F75 -> YES | M52: =HELPER!$G75 -> 59.75
B53: 8 | C53: =HELPER!$B$76 -> Laboratorium A | E53: =HELPER!$C$76 -> 825000 | G53: =HELPER!$E$76 -> Mon,Tue,Wed,Thu,Fri | J53: =HELPER!$D76 -> 2 | K53: =HELPER!$F76 -> YES | M53: =HELPER!$G76 -> 53.25
B54: 9 | C54: =HELPER!$B$77 -> Laboratorium F | E54: =HELPER!$C$77 -> 825000 | G54: =HELPER!$E$77 -> Mon,Tue,Wed,Thu,Fri | J54: =HELPER!$D77 -> 2 | K54: =HELPER!$F77 -> NO | M54: =HELPER!$G77 -> 45.5
B55: 10 | C55: =HELPER!$B$78 -> Laboratorium E | E55: =HELPER!$C$78 -> 850000 | G55: =HELPER!$E$78 -> Mon,Tue,Wed,Thu,Fri | J55: =HELPER!$D78 -> 2 | K55: =HELPER!$F78 -> YES | M55: =HELPER!$G78 -> 40.25

Sheet REFF
A1: lab_id | B1: lab_name | C1: pickup | D1: distance
A2: H001 | B2: Hospital A | C2: 0 | D2: 10
A3: H002 | B3: Hospital B | C3: 0 | D3: 10.5
A4: H003 | B4: Hospital C | C4: 0 | D4: 8.3
A5: H004 | B5: Hospital D | C5: 0 | D5: 9.5
A6: L001 | B6: Laboratorium A | C6: 1 | D6: 12.3
A7: L002 | B7: Laboratorium B | C7: 1 | D7: 7.8
A8: L003 | B8: Laboratorium C | C8: 0 | D8: 8.2
A9: L004 | B9: Laboratorium D | C9: 1 | D9: 11.1
A10: L005 | B10: Laboratorium E | C10: 1 | D10: 12
A11: L006 | B11: Laboratorium F | C11: 0 | D11: 8

Sheet TEST
A1: test_id | B1: test_name | C1: test_category
A2: TEST001 | B2: 17-OHP Neonatal | C2: Endocrinology & Hormones
A3: TEST002 | B3: ACTH | C3: Endocrinology & Hormones
A4: TEST003 | B4: Adiponectin | C4: Endocrinology & Hormones
A5: TEST004 | B5: AMA-ASMA | C5: Immunology & Serology
A6: TEST005 | B6: ANCA | C6: Immunology & Serology
A7: TEST006 | B7: Anti Mycoplasma IgG | C7: Immunology & Serology
A8: TEST007 | B8: Anti Mycoplasma IgM | C8: Immunology & Serology
A9: TEST008 | B9: anti Salmonella typhi IgG | C9: Immunology & Serology
A10: TEST009 | B10: anti Salmonella typhi IgM | C10: Immunology & Serology
A11: TEST010 | B11: Antibodi Trombosit | C11: Haematology
A12: TEST011 | B12: anti-ccp | C12: Immunology & Serology
... A79: TEST078 | B79: Zn | C79: Clinical Chemistry

Sheet SNP
A1: lab_id | B1: test_id | C1: price | D1: Monday | E1: Tuesday | F1: Wednesday | G1: Thursday | H1: Friday | I1: Saturday | J1: Sunday | K1: result_tat
A2: H001 | B2: TEST001 | C2: 100000 | D2: 1 | E2: 1 | F2: 1 | G2: 1 | H2: 1 | I2: 1 | J2: 0 | K2: 4
A3: H002 | B3: TEST001 | C3: 100000 | D3: 1 | E3: 1 | F3: 1 | G3: 1 | H3: 1 | I3: 1 | J3: 0 | K3: 4
A4: H003 | B4: TEST001 | C4: 90000 | D4: 1 | E4: 1 | F4: 1 | G4: 1 | H4: 1 | I4: 1 | J4: 0 | K4: 4
A5: H004 | B5: TEST001 | C5: 85000 | D5: 1 | E5: 1 | F5: 1 | G5: 1 | H5: 1 | I5: 1 | J5: 0 | K5: 5
A6: L001 | B6: TEST001 | C6: 125000 | D6: 1 | E6: 1 | F6: 1 | G6: 1 | H6: 1 | I6: 0 | J6: 0 | K6: 3
A7: L002 | B7: TEST001 | C7: 130000 | D7: 1 | E7: 1 | F7: 1 | G7: 1 | H7: 1 | I7: 1 | J7: 0 | K7: 3
A8: L003 | B8: TEST001 | C8: 120000 | D8: 1 | E8: 1 | F8: 1 | G8: 1 | H8: 1 | I8: 1 | J8: 0 | K8: 4
A9: L004 | B9: TEST001 | C9: 125000 | D9: 1 | E9: 1 | F9: 1 | G9: 1 | H9: 1 | I9: 1 | J9: 0 | K9: 3
A10: L005 | B10: TEST001 | C10: 120000 | D10: 1 | E10: 1 | F10: 1 | G10: 1 | H10: 1 | I10: 1 | J10: 0 | K10: 3
A11: L006 | B11: TEST001 | C11: 120000 | D11: 1 | E11: 1 | F11: 1 | G11: 1 | H11: 1 | I11: 0 | J11: 0 | K11: 3
A12: H001 | B12: TEST002 | C12: 1000000 | D12: 0 | E12: 0 | F12: 1 | G12: 0 | H12: 0 | I12: 0 | J12: 0 | K12: 3
A13: H002 | B13: TEST002 | C13: 950000 | D13: 0 | E13: 0 | F13: 0 | G13: 0 | H13: 1 | I13: 0 | J13: 0 | K13: 3
... A504: L006 | B504: TEST078 | C504: 580000 | D504: 1 | E504: 1 | F504: 1 | G504: 1 | H504: 1 | I504: 0 | J504: 0 | K504: 8

Sheet HELPER
A1: TEST NAME | C1: TEST TYPE | E1: TODAY IS
A2: =DASHBOARD!$G$5 -> C3 | C2: =DASHBOARD!$B$5 -> Routine | E2: =DASHBOARD!$M$5 -> Thursday
A3: TEST ID
A4: =INDEX(TEST!$A$2:$A$79,MATCH($A$2,TEST!$B$2:$B$79,0)) -> TEST019 | E4: =MATCH($E$2,{"Monday";"Tuesday";"Wednesday";"Thursday";"Friday";"Saturday";"Sunday"},0) -> 4
A8: TABLE CHEAP
A10: lab_id | B10: test_id | C10: price | D10: score
A11: {=_xlfn._xlws.SORT(_xlfn._xlws.FILTER(SNP!$A$2:$C$504,SNP!$B$2:$B$504=$A$4),3,1)} -> H001 | B11: TEST019 | C11: 600000 | D11: {=IF($A$11:$A$20="","",((100-(_xlfn.SEQUENCE(ROWS(A11:A20),1,0,1))*10)*IF($C$2="Routine",0.65,0.35)))} -> 65
A12: H003 | B12: TEST019 | C12: 600000 | D12: 58.5
A13: H004 | B13: TEST019 | C13: 610000 | D13: 52
A14: H002 | B14: TEST019 | C14: 615000 | D14: 45.5
A15: L002 | B15: TEST019 | C15: 800000 | D15: 39
A16: L003 | B16: TEST019 | C16: 815000 | D16: 32.5
A17: L004 | B17: TEST019 | C17: 820000 | D17: 26
A18: L001 | B18: TEST019 | C18: 825000 | D18: 19.5
A19: L006 | B19: TEST019 | C19: 825000 | D19: 13
A20: L005 | B20: TEST019 | C20: 850000 | D20: 6.5
A23: TABLE FAST
A25: lab_id | B25: test_id | C25: price | D25: Monday | E25: Tuesday | F25: Wednesday | G25: Thursday | H25: Friday | I25: Saturday | J25: Sunday | K25: result_tat | L25: wait_time | M25: rank | N25: score
A26: {=_xlfn._xlws.FILTER(SNP!$A$2:$K$504,SNP!$B$2:$B$504=$A$4)} -> H001 | B26: TEST019 | C26: 600000 | D26: 1 | E26: 1 | F26: 1 | G26: 1 | H26: 1 | I26: 1 | J26: 0 | K26: 2 | L26: =IF(A26="","",IFERROR(MATCH(1,INDEX(D26:J26,MATCH($E$2,SNP!$D$1:$J$1,0)):J26,0),MATCH(1,D26:J26,0)+5-MATCH($E$2,SNP!$D$1:$J$1,0))+$K26) -> 3 | M26: {=IF(L26="","",SUM(--(_xlfn.UNIQUE(_xlfn._xlws.FILTER($L$26:$L$35,$L$26:$L$35<>""))<L26))+1)} -> 2 | N26: =IF(L26="","",(110-M26*10)*IF($C$2="Routine",0.3,0.6)) -> 27
A27: H002 | B27: TEST019 | C27: 615000 | D27: 1 | E27: 1 | F27: 1 | G27: 1 | H27: 1 | I27: 1 | J27: 0 | K27: 2 | L27: =IF(A27="","",IFERROR(MATCH(1,INDEX(D27:J27,MATCH($E$2,SNP!$D$1:$J$1,0)):J27,0),MATCH(1,D27:J27,0)+5-MATCH($E$2,SNP!$D$1:$J$1,0))+$K27) -> 3 | M27: {=IF(L27="","",SUM(--(_xlfn.UNIQUE(_xlfn._xlws.FILTER($L$26:$L$35,$L$26:$L$35<>""))<L27))+1)} -> 2 | N27: =IF(L27="","",(110-M27*10)*IF($C$2="Routine",0.3,0.6)) -> 27
A28: H003 | B28: TEST019 | C28: 600000 | D28: 1 | E28: 1 | F28: 1 | G28: 1 | H28: 1 | I28: 1 | J28: 0 | K28: 2 | L28: =IF(A28="","",IFERROR(MATCH(1,INDEX(D28:J28,MATCH($E$2,SNP!$D$1:$J$1,0)):J28,0),MATCH(1,D28:J28,0)+5-MATCH($E$2,SNP!$D$1:$J$1,0))+$K28) -> 3 | M28: {=IF(L28="","",SUM(--(_xlfn.UNIQUE(_xlfn._xlws.FILTER($L$26:$L$35,$L$26:$L$35<>""))<L28))+1)} -> 2 | N28: =IF(L28="","",(110-M28*10)*IF($C$2="Routine",0.3,0.6)) -> 27
A29: H004 | B29: TEST019 | C29: 610000 | D29: 1 | E29: 1 | F29: 1 | G29: 1 | H29: 1 | I29: 1 | J29: 0 | K29: 2 | L29: =IF(A29="","",IFERROR(MATCH(1,INDEX(D29:J29,MATCH($E$2,SNP!$D$1:$J$1,0)):J29,0),MATCH(1,D29:J29,0)+5-MATCH($E$2,SNP!$D$1:$J$1,0))+$K29) -> 3 | M29: {=IF(L29="","",SUM(--(_xlfn.UNIQUE(_xlfn._xlws.FILTER($L$26:$L$35,$L$26:$L$35<>""))<L29))+1)} -> 2 | N29: =IF(L29="","",(110-M29*10)*IF($C$2="Routine",0.3,0.6)) -> 27
A30: L001 | B30: TEST019 | C30: 825000 | D30: 1 | E30: 1 | F30: 1 | G30: 1 | H30: 1 | I30: 0 | J30: 0 | K30: 1 | L30: =IF(A30="","",IFERROR(MATCH(1,INDEX(D30:J30,MATCH($E$2,SNP!$D$1:$J$1,0)):J30,0),MATCH(1,D30:J30,0)+5-MATCH($E$2,SNP!$D$1:$J$1,0))+$K30) -> 2 | M30: {=IF(L30="","",SUM(--(_xlfn.UNIQUE(_xlfn._xlws.FILTER($L$26:$L$35,$L$26:$L$35<>""))<L30))+1)} -> 1 | N30: =IF(L30="","",(110-M30*10)*IF($C$2="Routine",0.3,0.6)) -> 30
A31: L002 | B31: TEST019 | C31: 800000 | D31: 1 | E31: 1 | F31: 1 | G31: 1 | H31: 1 | I31: 0 | J31: 0 | K31: 1 | L31: =IF(A31="","",IFERROR(MATCH(1,INDEX(D31:J31,MATCH($E$2,SNP!$D$1:$J$1,0)):J31,0),MATCH(1,D31:J31,0)+5-MATCH($E$2,SNP!$D$1:$J$1,0))+$K31) -> 2 | M31: {=IF(L31="","",SUM(--(_xlfn.UNIQUE(_xlfn._xlws.FILTER($L$26:$L$35,$L$26:$L$35<>""))<L31))+1)} -> 1 | N31: =IF(L31="","",(110-M31*10)*IF($C$2="Routine",0.3,0.6)) -> 30
A32: L003 | B32: TEST019 | C32: 815000 | D32: 1 | E32: 1 | F32: 1 | G32: 1 | H32: 1 | I32: 0 | J32: 0 | K32: 1 | L32: =IF(A32="","",IFERROR(MATCH(1,INDEX(D32:J32,MATCH($E$2,SNP!$D$1:$J$1,0)):J32,0),MATCH(1,D32:J32,0)+5-MATCH($E$2,SNP!$D$1:$J$1,0))+$K32) -> 2 | M32: {=IF(L32="","",SUM(--(_xlfn.UNIQUE(_xlfn._xlws.FILTER($L$26:$L$35,$L$26:$L$35<>""))<L32))+1)} -> 1 | N32: =IF(L32="","",(110-M32*10)*IF($C$2="Routine",0.3,0.6)) -> 30
A33: L004 | B33: TEST019 | C33: 820000 | D33: 1 | E33: 1 | F33: 1 | G33: 1 | H33: 1 | I33: 0 | J33: 0 | K33: 1 | L33: =IF(A33="","",IFERROR(MATCH(1,INDEX(D33:J33,MATCH($E$2,SNP!$D$1:$J$1,0)):J33,0),MATCH(1,D33:J33,0)+5-MATCH($E$2,SNP!$D$1:$J$1,0))+$K33) -> 2 | M33: {=IF(L33="","",SUM(--(_xlfn.UNIQUE(_xlfn._xlws.FILTER($L$26:$L$35,$L$26:$L$35<>""))<L33))+1)} -> 1 | N33: =IF(L33="","",(110-M33*10)*IF($C$2="Routine",0.3,0.6)) -> 30
A34: L005 | B34: TEST019 | C34: 850000 | D34: 1 | E34: 1 | F34: 1 | G34: 1 | H34: 1 | I34: 0 | J34: 0 | K34: 1 | L34: =IF(A34="","",IFERROR(MATCH(1,INDEX(D34:J34,MATCH($E$2,SNP!$D$1:$J$1,0)):J34,0),MATCH(1,D34:J34,0)+5-MATCH($E$2,SNP!$D$1:$J$1,0))+$K34) -> 2 | M34: {=IF(L34="","",SUM(--(_xlfn.UNIQUE(_xlfn._xlws.FILTER($L$26:$L$35,$L$26:$L$35<>""))<L34))+1)} -> 1 | N34: =IF(L34="","",(110-M34*10)*IF($C$2="Routine",0.3,0.6)) -> 30
A35: L006 | B35: TEST019 | C35: 825000 | D35: 1 | E35: 1 | F35: 1 | G35: 1 | H35: 1 | I35: 0 | J35: 0 | K35: 1 | L35: =IF(A35="","",IFERROR(MATCH(1,INDEX(D35:J35,MATCH($E$2,SNP!$D$1:$J$1,0)):J35,0),MATCH(1,D35:J35,0)+5-MATCH($E$2,SNP!$D$1:$J$1,0))+$K35) -> 2 | M35: {=IF(L35="","",SUM(--(_xlfn.UNIQUE(_xlfn._xlws.FILTER($L$26:$L$35,$L$26:$L$35<>""))<L35))+1)} -> 1 | N35: =IF(L35="","",(110-M35*10)*IF($C$2="Routine",0.3,0.6)) -> 30
A38: TABLE BONUS
A40: lab_id | B40: pickup | C40: distance | D40: score
A41: L001 | B41: 1 | C41: 12.3 | D41: =75*0.05 -> 3.75
A42: L002 | B42: 1 | C42: 7.8 | D42: =100*0.05 -> 5
A43: L003 | B43: 0 | C43: 8.2 | D43: =10*0.05 -> 0.5
A44: L004 | B44: 1 | C44: 11.1 | D44: =75*0.05 -> 3.75
A45: L005 | B45: 1 | C45: 12 | D45: =75*0.05 -> 3.75
A46: L006 | B46: 0 | C46: 8 | D46: =50*0.05 -> 2.5
A47: H001 | B47: 0 | C47: 10 | D47: =25*0.05 -> 1.25
A48: H002 | B48: 0 | C48: 10.5 | D48: =25*0.05 -> 1.25
A49: H003 | B49: 0 | C49: 8.3 | D49: =50*0.05 -> 2.5
A50: H004 | B50: 0 | C50: 9.5 | D50: =25*0.05 -> 1.25
...

Sheet CHARTS
A1: "BY PRICE" CHARTS
C3: Price | D3: Refference
A4: {=_xlfn._xlws.SORT(_xlfn._xlws.FILTER(SNP!$A$2:$C$504,SNP!$B$2:$B$504=HELPER!$A$4),3,1)} -> H001 | B4: TEST019 | C4: 600000 | D4: =IFERROR(VLOOKUP(A4,REFF!$A$2:$B$11,2,FALSE),"") -> Hospital A
A5: H003 | B5: TEST019 | C5: 600000 | D5: =IFERROR(VLOOKUP(A5,REFF!$A$2:$B$11,2,FALSE),"") -> Hospital C
A6: H004 | B6: TEST019 | C6: 610000 | D6: =IFERROR(VLOOKUP(A6,REFF!$A$2:$B$11,2,FALSE),"") -> Hospital D
A7: H002 | B7: TEST019 | C7: 615000 | D7: =IFERROR(VLOOKUP(A7,REFF!$A$2:$B$11,2,FALSE),"") -> Hospital B
A8: L002 | B8: TEST019 | C8: 800000 | D8: =IFERROR(VLOOKUP(A8,REFF!$A$2:$B$11,2,FALSE),"") -> Laboratorium B
A9: L003 | B9: TEST019 | C9: 815000 | D9: =IFERROR(VLOOKUP(A9,REFF!$A$2:$B$11,2,FALSE),"") -> Laboratorium C
A10: L004 | B10: TEST019 | C10: 820000 | D10: =IFERROR(VLOOKUP(A10,REFF!$A$2:$B$11,2,FALSE),"") -> Laboratorium D
A11: L001 | B11: TEST019 | C11: 825000 | D11: =IFERROR(VLOOKUP(A11,REFF!$A$2:$B$11,2,FALSE),"") -> Laboratorium A
A12: L006 | B12: TEST019 | C12: 825000 | D12: =IFERROR(VLOOKUP(A12,REFF!$A$2:$B$11,2,FALSE),"") -> Laboratorium F
A13: L005 | B13: TEST019 | C13: 850000 | D13: =IFERROR(VLOOKUP(A13,REFF!$A$2:$B$11,2,FALSE),"") -> Laboratorium E
A20: "BY TAT" CHARTS
A21: {=HELPER!A26:$A$35} -> H001 | B21: {=HELPER!L26:L35} -> 3 | C21: =IFERROR(VLOOKUP(A21,REFF!$A$2:$B$11,2,FALSE),"") -> Hospital A
A22: H002 | B22: 3 | C22: =IFERROR(VLOOKUP(A22,REFF!$A$2:$B$11,2,FALSE),"") -> Hospital B
A23: H003 | B23: 3 | C23: =IFERROR(VLOOKUP(A23,REFF!$A$2:$B$11,2,FALSE),"") -> Hospital C
A24: H004 | B24: 3 | C24: =IFERROR(VLOOKUP(A24,REFF!$A$2:$B$11,2,FALSE),"") -> Hospital D
A25: L001 | B25: 2 | C25: =IFERROR(VLOOKUP(A25,REFF!$A$2:$B$11,2,FALSE),"") -> Laboratorium A
A26: L002 | B26: 2 | C26: =IFERROR(VLOOKUP(A26,REFF!$A$2:$B$11,2,FALSE),"") -> Laboratorium B
A27: L003 | B27: 2 | C27: =IFERROR(VLOOKUP(A27,REFF!$A$2:$B$11,2,FALSE),"") -> Laboratorium C
A28: L004 | B28: 2 | C28: =IFERROR(VLOOKUP(A28,REFF!$A$2:$B$11,2,FALSE),"") -> Laboratorium D
A29: L005 | B29: 2 | C29: =IFERROR(VLOOKUP(A29,REFF!$A$2:$B$11,2,FALSE),"") -> Laboratorium E
A30: L006 | B30: 2 | C30: =IFERROR(VLOOKUP(A30,REFF!$A$2:$B$11,2,FALSE),"") -> Laboratorium F
A33: {=_xlfn._xlws.SORT($B$21:$C$30,1,1)} -> 2 | B33: Laboratorium A
A34: 2 | B34: Laboratorium B
A35: 2 | B35: Laboratorium C
A36: 2 | B36: Laboratorium D
A37: 2 | B37: Laboratorium E
A38: 2 | B38: Laboratorium F
A39: 3 | B39: Hospital A
A40: 3 | B40: Hospital B
A41: 3 | B41: Hospital C
A42: 3 | B42: Hospital D
